<?xml version='1.0'?>
<robot name="mob_robot">

  <!-- Base Link is chest mesh bracet-->
  <link name="base_link">
    <visual>
      <origin rpy="0 0 0" xyz="0 0 0"/>
      <geometry>
        <mesh filename="file:///home/jiovanni/catkin_ws/src/mob/urdf/Chest.dae" scale="0.02905, 0.09013, 0.04335"/>
      </geometry>
    </visual>
    <!-- Collision on base_link-->
    <collision>
      <origin rpy="0 0 0" xyz="0 0 0"/>
      <geometry>
        <mesh filename="file:///home/jiovanni/catkin_ws/src/mob/urdf/Chest.dae"/>
      </geometry>
    </collision>
    <!--Mass in kilograms-->
    <inertial>
      <mass value="0.0005"/>
      <inertia ixx="0.13" ixy="0.0" ixz="0.0" iyy="0.21" iyz="0.0" izz="0.13" />
    </inertial>
  </link>

  <!--head motor-->
  <link name="head_motor">
   <visual>
      <origin rpy="0 0 0" xyz="0 0 0"/>
      <geometry>
        <mesh filename="file:///home/jiovanni/catkin_ws/src/mob/urdf/Chest.dae" scale="0.02905, 0.09013, 0.04335"/>
      </geometry>
    </visual>
    <!-- Collision on base_link-->
    <collision>
      <origin rpy="0 0 0" xyz="0 0 0"/>
      <geometry>
        <mesh filename="file:///home/jiovanni/catkin_ws/src/mob/urdf/Chest.dae"/>
      </geometry>
    </collision>
    <!--Mass in kilograms-->
    <inertial>
      <mass value="0.0005"/>
      <inertia ixx="0.13" ixy="0.0" ixz="0.0" iyy="0.21" iyz="0.0" izz="0.13" />
    </inertial>
  </link>

  <!--This is the head/chest joint -->
  <joint name="head_joint" type="revolute">
    <limit effort="1000.0" lower="-1.0" upper="1.0" velocity="0.5"/>
    <parent link="base_link"/>
    <child link="head_motor"/>
    <origin xyz="0 0 0.07" rpy="0 0 0" />
    <axis xyz="0 0 1" />
  </joint>

</robot>
