<sdf version='1.6'>
  <model name='mob_robot'>
    <link name='base_link'>
      <pose frame=''>0 0 0 0 -0 0</pose>
      <inertial>
        <pose frame=''>0 0 0 0 -0 0</pose>
        <mass>0.0005</mass>
        <inertia>
          <ixx>0.13</ixx>
          <ixy>0</ixy>
          <ixz>0</ixz>
          <iyy>0.21</iyy>
          <iyz>0</iyz>
          <izz>0.13</izz>
        </inertia>
      </inertial>
      <collision name='base_link_collision'>
        <pose frame=''>-0.028 -0.01 0 0 -0 0</pose>
        <geometry>
          <mesh>
            <scale>0.01 0.01 0.01</scale>
            <uri>file:///home/jiovanni/catkin_ws/src/mob/urdf/Chest.dae</uri>
          </mesh>
        </geometry>
      </collision>
      <visual name='base_link_visual'>
        <pose frame=''>-0.028 -0.01 0 0 -0 0</pose>
        <geometry>
          <mesh>
            <scale>0.01 0.01 0.01</scale>
            <uri>file:///home/jiovanni/catkin_ws/src/mob/urdf/Chest.dae</uri>
          </mesh>
        </geometry>
      </visual>
    </link>
    <link name='head_motor'>
      <pose frame=''>0 0.0037 0.044 0 -0 0</pose>
      <inertial>
        <pose frame=''>0 0 0 0 -0 0</pose>
        <mass>0.0005</mass>
        <inertia>
          <ixx>0.13</ixx>
          <ixy>0</ixy>
          <ixz>0</ixz>
          <iyy>0.21</iyy>
          <iyz>0</iyz>
          <izz>0.13</izz>
        </inertia>
      </inertial>
      <collision name='head_motor_collision'>
        <pose frame=''>-0.0035 -0.015 0 0 -0 0</pose>
        <geometry>
          <mesh>
            <scale>0.01 0.01 0.01</scale>
            <uri>file:///home/jiovanni/catkin_ws/src/mob/urdf/Head.dae</uri>
          </mesh>
        </geometry>
      </collision>
      <visual name='head_motor_visual'>
        <pose frame=''>-0.0035 -0.015 0 0 -0 0</pose>
        <geometry>
          <mesh>
            <scale>0.01 0.01 0.01</scale>
            <uri>file:///home/jiovanni/catkin_ws/src/mob/urdf/Head.dae</uri>
          </mesh>
        </geometry>
      </visual>
    </link>
    <joint name='head_joint' type='revolute'>
      <child>head_motor</child>
      <parent>base_link</parent>
      <axis>
        <xyz>0 0 1</xyz>
        <limit>
          <lower>-1</lower>
          <upper>1</upper>
          <effort>1000</effort>
          <velocity>0.5</velocity>
        </limit>
        <dynamics>
          <spring_reference>0</spring_reference>
          <spring_stiffness>0</spring_stiffness>
        </dynamics>
        <use_parent_model_frame>1</use_parent_model_frame>
      </axis>
    </joint>
    <link name='left_shoulder'>
      <pose frame=''>0.03 0.003 0.039 0 -0 0</pose>
      <inertial>
        <pose frame=''>0 0 0 0 -0 0</pose>
        <mass>0.0005</mass>
        <inertia>
          <ixx>0.13</ixx>
          <ixy>0</ixy>
          <ixz>0</ixz>
          <iyy>0.21</iyy>
          <iyz>0</iyz>
          <izz>0.13</izz>
        </inertia>
      </inertial>
      <collision name='left_shoulder_collision'>
        <pose frame=''>0.0143 0.0101 0.0134 0 -0 0</pose>
        <geometry>
          <mesh>
            <scale>0.01 0.01 0.01</scale>
            <uri>file:///home/jiovanni/catkin_ws/src/mob/urdf/LeftShoulder.dae</uri>
          </mesh>
        </geometry>
      </collision>
      <visual name='left_shoulder_visual'>
        <pose frame=''>0.0143 0.0101 0.0134 3.14159 1.57079 3e-06</pose>
        <geometry>
          <mesh>
            <scale>0.01 0.01 0.01</scale>
            <uri>file:///home/jiovanni/catkin_ws/src/mob/urdf/LeftShoulder.dae</uri>
          </mesh>
        </geometry>
      </visual>
    </link>
    <joint name='left_shoulder_joint' type='revolute'>
      <child>left_shoulder</child>
      <parent>base_link</parent>
      <axis>
        <xyz>1 0 0</xyz>
        <limit>
          <lower>-1</lower>
          <upper>1</upper>
          <effort>1000</effort>
          <velocity>0.5</velocity>
        </limit>
        <dynamics>
          <spring_reference>0</spring_reference>
          <spring_stiffness>0</spring_stiffness>
        </dynamics>
        <use_parent_model_frame>1</use_parent_model_frame>
      </axis>
    </joint>
    <link name='left_arm'>
      <pose frame=''>0.0394 -0.0019 0.0476 0 -0 0</pose>
      <inertial>
        <pose frame=''>0 0 0 0 -0 0</pose>
        <mass>0.0005</mass>
        <inertia>
          <ixx>0.13</ixx>
          <ixy>0</ixy>
          <ixz>0</ixz>
          <iyy>0.21</iyy>
          <iyz>0</iyz>
          <izz>0.13</izz>
        </inertia>
      </inertial>
      <collision name='left_arm_collision'>
        <pose frame=''>0.007 0.015 -0.044 0 -0 0</pose>
        <geometry>
          <mesh>
            <scale>0.01 0.01 0.01</scale>
            <uri>file:///home/jiovanni/catkin_ws/src/mob/urdf/LeftArm.dae</uri>
          </mesh>
        </geometry>
      </collision>
      <visual name='left_arm_visual'>
        <pose frame=''>0.007 0.015 -0.044 0 -0 3.14159</pose>
        <geometry>
          <mesh>
            <scale>0.01 0.01 0.01</scale>
            <uri>file:///home/jiovanni/catkin_ws/src/mob/urdf/LeftArm.dae</uri>
          </mesh>
        </geometry>
      </visual>
    </link>
    <joint name='left_arm_joint' type='revolute'>
      <child>left_arm</child>
      <parent>left_shoulder</parent>
      <axis>
        <xyz>0 1 0</xyz>
        <limit>
          <lower>-1</lower>
          <upper>1</upper>
          <effort>1000</effort>
          <velocity>0.5</velocity>
        </limit>
        <dynamics>
          <spring_reference>0</spring_reference>
          <spring_stiffness>0</spring_stiffness>
        </dynamics>
        <use_parent_model_frame>1</use_parent_model_frame>
      </axis>
    </joint>
    <link name='left_hand'>
      <pose frame=''>0.0401 0.0031 0.0086 0 -0 0</pose>
      <inertial>
        <pose frame=''>0 0 0 0 -0 0</pose>
        <mass>0.0005</mass>
        <inertia>
          <ixx>0.13</ixx>
          <ixy>0</ixy>
          <ixz>0</ixz>
          <iyy>0.21</iyy>
          <iyz>0</iyz>
          <izz>0.13</izz>
        </inertia>
      </inertial>
      <collision name='left_hand_collision'>
        <pose frame=''>-0.0052 -0.011 -0.0282 0 -0 0</pose>
        <geometry>
          <mesh>
            <scale>0.01 0.01 0.01</scale>
            <uri>file:///home/jiovanni/catkin_ws/src/mob/urdf/LeftHand.dae</uri>
          </mesh>
        </geometry>
      </collision>
      <visual name='left_hand_visual'>
        <pose frame=''>-0.0052 -0.011 -0.0282 0 -0 0</pose>
        <geometry>
          <mesh>
            <scale>0.01 0.01 0.01</scale>
            <uri>file:///home/jiovanni/catkin_ws/src/mob/urdf/LeftHand.dae</uri>
          </mesh>
        </geometry>
      </visual>
    </link>
    <joint name='left_hand_joint' type='revolute'>
      <child>left_hand</child>
      <parent>left_arm</parent>
      <axis>
        <xyz>0 1 0</xyz>
        <limit>
          <lower>-1</lower>
          <upper>1</upper>
          <effort>1000</effort>
          <velocity>0.5</velocity>
        </limit>
        <dynamics>
          <spring_reference>0</spring_reference>
          <spring_stiffness>0</spring_stiffness>
        </dynamics>
        <use_parent_model_frame>1</use_parent_model_frame>
      </axis>
    </joint>
    <link name='left_thigh'>
      <pose frame=''>0.018 0 0.0058 0 -0 0</pose>
      <inertial>
        <pose frame=''>0 0 0 0 -0 0</pose>
        <mass>0.0005</mass>
        <inertia>
          <ixx>0.13</ixx>
          <ixy>0</ixy>
          <ixz>0</ixz>
          <iyy>0.21</iyy>
          <iyz>0</iyz>
          <izz>0.13</izz>
        </inertia>
      </inertial>
      <collision name='left_thigh_collision'>
        <pose frame=''>-0.011 -0.011 -0.03815 0 -0 0</pose>
        <geometry>
          <mesh>
            <scale>0.01 0.01 0.01</scale>
            <uri>file:///home/jiovanni/catkin_ws/src/mob/urdf/LeftThigh.dae</uri>
          </mesh>
        </geometry>
      </collision>
      <visual name='left_thigh_visual'>
        <pose frame=''>-0.011 -0.011 -0.03815 0 -0 0</pose>
        <geometry>
          <mesh>
            <scale>0.01 0.01 0.01</scale>
            <uri>file:///home/jiovanni/catkin_ws/src/mob/urdf/LeftThigh.dae</uri>
          </mesh>
        </geometry>
      </visual>
    </link>
    <joint name='left_thigh_joint' type='revolute'>
      <child>left_thigh</child>
      <parent>base_link</parent>
      <axis>
        <xyz>0 1 0</xyz>
        <limit>
          <lower>-1</lower>
          <upper>1</upper>
          <effort>1000</effort>
          <velocity>0.5</velocity>
        </limit>
        <dynamics>
          <spring_reference>0</spring_reference>
          <spring_stiffness>0</spring_stiffness>
        </dynamics>
        <use_parent_model_frame>1</use_parent_model_frame>
      </axis>
    </joint>
    <link name='left_knee'>
      <pose frame=''>0.015 -8e-05 -0.0272 0 -0 0</pose>
      <inertial>
        <pose frame=''>0 0 0 0 -0 0</pose>
        <mass>0.0005</mass>
        <inertia>
          <ixx>0.13</ixx>
          <ixy>0</ixy>
          <ixz>0</ixz>
          <iyy>0.21</iyy>
          <iyz>0</iyz>
          <izz>0.13</izz>
        </inertia>
      </inertial>
      <collision name='left_knee_collision'>
        <pose frame=''>-0.0072 -0.007 -0.038 0 -0 0</pose>
        <geometry>
          <mesh>
            <scale>0.01 0.01 0.01</scale>
            <uri>file:///home/jiovanni/catkin_ws/src/mob/urdf/LeftKnee.dae</uri>
          </mesh>
        </geometry>
      </collision>
      <visual name='left_knee_visual'>
        <pose frame=''>-0.0072 -0.007 -0.038 0 -0 0</pose>
        <geometry>
          <mesh>
            <scale>0.01 0.01 0.01</scale>
            <uri>file:///home/jiovanni/catkin_ws/src/mob/urdf/LeftKnee.dae</uri>
          </mesh>
        </geometry>
      </visual>
    </link>
    <joint name='left_knee_joint' type='revolute'>
      <child>left_knee</child>
      <parent>left_thigh</parent>
      <axis>
        <xyz>1 0 0</xyz>
        <limit>
          <lower>-1</lower>
          <upper>1</upper>
          <effort>1000</effort>
          <velocity>0.5</velocity>
        </limit>
        <dynamics>
          <spring_reference>0</spring_reference>
          <spring_stiffness>0</spring_stiffness>
        </dynamics>
        <use_parent_model_frame>1</use_parent_model_frame>
      </axis>
    </joint>
    <link name='left_shin'>
      <pose frame=''>0.01474 -0.00016 -0.0602 0 -0 0</pose>
      <inertial>
        <pose frame=''>0 0 0 0 -0 0</pose>
        <mass>0.0005</mass>
        <inertia>
          <ixx>0.13</ixx>
          <ixy>0</ixy>
          <ixz>0</ixz>
          <iyy>0.21</iyy>
          <iyz>0</iyz>
          <izz>0.13</izz>
        </inertia>
      </inertial>
      <collision name='left_shin_collision'>
        <pose frame=''>-0.0081 -0.0143 -0.0286 0 -0 0</pose>
        <geometry>
          <mesh>
            <scale>0.01 0.01 0.01</scale>
            <uri>file:///home/jiovanni/catkin_ws/src/mob/urdf/LeftShin.dae</uri>
          </mesh>
        </geometry>
      </collision>
      <visual name='left_shin_visual'>
        <pose frame=''>-0.0081 -0.0143 -0.0286 0 -0 0</pose>
        <geometry>
          <mesh>
            <scale>0.01 0.01 0.01</scale>
            <uri>file:///home/jiovanni/catkin_ws/src/mob/urdf/LeftShin.dae</uri>
          </mesh>
        </geometry>
      </visual>
    </link>
    <joint name='left_shin_joint' type='revolute'>
      <child>left_shin</child>
      <parent>left_knee</parent>
      <axis>
        <xyz>1 0 0</xyz>
        <limit>
          <lower>-1</lower>
          <upper>1</upper>
          <effort>1000</effort>
          <velocity>0.5</velocity>
        </limit>
        <dynamics>
          <spring_reference>0</spring_reference>
          <spring_stiffness>0</spring_stiffness>
        </dynamics>
        <use_parent_model_frame>1</use_parent_model_frame>
      </axis>
    </joint>
    <link name='left_ankle'>
      <pose frame=''>0.01434 -0.00966 -0.0842 0 -0 0</pose>
      <inertial>
        <pose frame=''>0 0 0 0 -0 0</pose>
        <mass>0.0005</mass>
        <inertia>
          <ixx>0.13</ixx>
          <ixy>0</ixy>
          <ixz>0</ixz>
          <iyy>0.21</iyy>
          <iyz>0</iyz>
          <izz>0.13</izz>
        </inertia>
      </inertial>
      <collision name='left_ankle_collision'>
        <pose frame=''>-0.0068 -0.0068 -0.0225 0 -0 0</pose>
        <geometry>
          <mesh>
            <scale>0.01 0.01 0.01</scale>
            <uri>file:///home/jiovanni/catkin_ws/src/mob/urdf/LeftAnkle.dae</uri>
          </mesh>
        </geometry>
      </collision>
      <visual name='left_ankle_visual'>
        <pose frame=''>-0.0068 -0.0068 -0.0225 0 -0 0</pose>
        <geometry>
          <mesh>
            <scale>0.01 0.01 0.01</scale>
            <uri>file:///home/jiovanni/catkin_ws/src/mob/urdf/LeftAnkle.dae</uri>
          </mesh>
        </geometry>
      </visual>
    </link>
    <joint name='left_ankle_joint' type='revolute'>
      <child>left_ankle</child>
      <parent>left_shin</parent>
      <axis>
        <xyz>1 0 0</xyz>
        <limit>
          <lower>-1</lower>
          <upper>1</upper>
          <effort>1000</effort>
          <velocity>0.5</velocity>
        </limit>
        <dynamics>
          <spring_reference>0</spring_reference>
          <spring_stiffness>0</spring_stiffness>
        </dynamics>
        <use_parent_model_frame>1</use_parent_model_frame>
      </axis>
    </joint>
    <link name='left_foot'>
      <pose frame=''>0.02144 -0.01166 -0.1022 0 -0 0</pose>
      <inertial>
        <pose frame=''>0 0 0 0 -0 0</pose>
        <mass>0.0005</mass>
        <inertia>
          <ixx>0.13</ixx>
          <ixy>0</ixy>
          <ixz>0</ixz>
          <iyy>0.21</iyy>
          <iyz>0</iyz>
          <izz>0.13</izz>
        </inertia>
      </inertial>
      <collision name='left_foot_collision'>
        <pose frame=''>-0.018 -0.026 -0.0078 0 -0 0</pose>
        <geometry>
          <mesh>
            <scale>0.00046 0.00046 0.00046</scale>
            <uri>file:///home/jiovanni/catkin_ws/src/mob/urdf/LeftFoot.dae</uri>
          </mesh>
        </geometry>
      </collision>
      <visual name='left_foot_visual'>
        <pose frame=''>-0.018 -0.026 -0.0078 0 -0 0</pose>
        <geometry>
          <mesh>
            <scale>0.00046 0.00046 0.00046</scale>
            <uri>file:///home/jiovanni/catkin_ws/src/mob/urdf/LeftFoot.dae</uri>
          </mesh>
        </geometry>
      </visual>
    </link>
    <joint name='left_foot_joint' type='revolute'>
      <child>left_foot</child>
      <parent>left_ankle</parent>
      <axis>
        <xyz>0 1 0</xyz>
        <limit>
          <lower>-1</lower>
          <upper>1</upper>
          <effort>1000</effort>
          <velocity>0.5</velocity>
        </limit>
        <dynamics>
          <spring_reference>0</spring_reference>
          <spring_stiffness>0</spring_stiffness>
        </dynamics>
        <use_parent_model_frame>1</use_parent_model_frame>
      </axis>
    </joint>
    <link name='right_shoulder'>
      <pose frame=''>-0.027 0.003 0.039 0 -0 0</pose>
      <inertial>
        <pose frame=''>0 0 0 0 -0 0</pose>
        <mass>0.0005</mass>
        <inertia>
          <ixx>0.13</ixx>
          <ixy>0</ixy>
          <ixz>0</ixz>
          <iyy>0.21</iyy>
          <iyz>0</iyz>
          <izz>0.13</izz>
        </inertia>
      </inertial>
      <collision name='right_shoulder_collision'>
        <pose frame=''>-0.017 -0.0101 0.0134 3.14159 1.57079 3.14159</pose>
        <geometry>
          <mesh>
            <scale>0.01 0.01 0.01</scale>
            <uri>file:///home/jiovanni/catkin_ws/src/mob/urdf/RightShoulder.dae</uri>
          </mesh>
        </geometry>
      </collision>
      <visual name='right_shoulder_visual'>
        <pose frame=''>-0.017 -0.0101 0.0134 3.14159 1.57079 3.14159</pose>
        <geometry>
          <mesh>
            <scale>0.01 0.01 0.01</scale>
            <uri>file:///home/jiovanni/catkin_ws/src/mob/urdf/RightShoulder.dae</uri>
          </mesh>
        </geometry>
      </visual>
    </link>
    <joint name='right_shoulder_joint' type='revolute'>
      <child>right_shoulder</child>
      <parent>base_link</parent>
      <axis>
        <xyz>1 0 0</xyz>
        <limit>
          <lower>-1</lower>
          <upper>1</upper>
          <effort>1000</effort>
          <velocity>0.5</velocity>
        </limit>
        <dynamics>
          <spring_reference>0</spring_reference>
          <spring_stiffness>0</spring_stiffness>
        </dynamics>
        <use_parent_model_frame>1</use_parent_model_frame>
      </axis>
    </joint>
    <link name='right_arm'>
      <pose frame=''>-0.039 0.006 0.048 0 -0 0</pose>
      <inertial>
        <pose frame=''>0 0 0 0 -0 0</pose>
        <mass>0.0005</mass>
        <inertia>
          <ixx>0.13</ixx>
          <ixy>0</ixy>
          <ixz>0</ixz>
          <iyy>0.21</iyy>
          <iyz>0</iyz>
          <izz>0.13</izz>
        </inertia>
      </inertial>
      <collision name='right_arm_collision'>
        <pose frame=''>-0.007 -0.013 -0.044 0 -0 0</pose>
        <geometry>
          <mesh>
            <scale>0.01 0.01 0.01</scale>
            <uri>file:///home/jiovanni/catkin_ws/src/mob/urdf/RightArm.dae</uri>
          </mesh>
        </geometry>
      </collision>
      <visual name='right_arm_visual'>
        <pose frame=''>-0.007 -0.013 -0.044 0 -0 0</pose>
        <geometry>
          <mesh>
            <scale>0.01 0.01 0.01</scale>
            <uri>file:///home/jiovanni/catkin_ws/src/mob/urdf/RightArm.dae</uri>
          </mesh>
        </geometry>
      </visual>
    </link>
    <joint name='right_arm_joint' type='revolute'>
      <child>right_arm</child>
      <parent>right_shoulder</parent>
      <axis>
        <xyz>0 1 0</xyz>
        <limit>
          <lower>-1</lower>
          <upper>1</upper>
          <effort>1000</effort>
          <velocity>0.5</velocity>
        </limit>
        <dynamics>
          <spring_reference>0</spring_reference>
          <spring_stiffness>0</spring_stiffness>
        </dynamics>
        <use_parent_model_frame>1</use_parent_model_frame>
      </axis>
    </joint>
    <link name='right_hand'>
      <pose frame=''>-0.0398 0.005 0.009 0 -0 0</pose>
      <inertial>
        <pose frame=''>0 0 0 0 -0 0</pose>
        <mass>0.0005</mass>
        <inertia>
          <ixx>0.13</ixx>
          <ixy>0</ixy>
          <ixz>0</ixz>
          <iyy>0.21</iyy>
          <iyz>0</iyz>
          <izz>0.13</izz>
        </inertia>
      </inertial>
      <collision name='right_hand_collision'>
        <pose frame=''>-0.0066 -0.011 -0.0282 0 -0 0</pose>
        <geometry>
          <mesh>
            <scale>0.01 0.01 0.01</scale>
            <uri>file:///home/jiovanni/catkin_ws/src/mob/urdf/RightHand.dae</uri>
          </mesh>
        </geometry>
      </collision>
      <visual name='right_hand_visual'>
        <pose frame=''>-0.0066 -0.011 -0.0282 0 -0 0</pose>
        <geometry>
          <mesh>
            <scale>0.01 0.01 0.01</scale>
            <uri>file:///home/jiovanni/catkin_ws/src/mob/urdf/RightHand.dae</uri>
          </mesh>
        </geometry>
      </visual>
    </link>
    <joint name='right_hand_joint' type='revolute'>
      <child>right_hand</child>
      <parent>right_arm</parent>
      <axis>
        <xyz>0 1 0</xyz>
        <limit>
          <lower>-1</lower>
          <upper>1</upper>
          <effort>1000</effort>
          <velocity>0.5</velocity>
        </limit>
        <dynamics>
          <spring_reference>0</spring_reference>
          <spring_stiffness>0</spring_stiffness>
        </dynamics>
        <use_parent_model_frame>1</use_parent_model_frame>
      </axis>
    </joint>
    <link name='right_thigh'>
      <pose frame=''>-0.0167 0 0.006 0 -0 0</pose>
      <inertial>
        <pose frame=''>0 0 0 0 -0 0</pose>
        <mass>0.0005</mass>
        <inertia>
          <ixx>0.13</ixx>
          <ixy>0</ixy>
          <ixz>0</ixz>
          <iyy>0.21</iyy>
          <iyz>0</iyz>
          <izz>0.13</izz>
        </inertia>
      </inertial>
      <collision name='right_thigh_collision'>
        <pose frame=''>-0.0118 -0.011 -0.038 0 -0 0</pose>
        <geometry>
          <mesh>
            <scale>0.01 0.01 0.01</scale>
            <uri>file:///home/jiovanni/catkin_ws/src/mob/urdf/RightThigh.dae</uri>
          </mesh>
        </geometry>
      </collision>
      <visual name='right_thigh_visual'>
        <pose frame=''>-0.0118 -0.011 -0.038 0 -0 0</pose>
        <geometry>
          <mesh>
            <scale>0.01 0.01 0.01</scale>
            <uri>file:///home/jiovanni/catkin_ws/src/mob/urdf/RightThigh.dae</uri>
          </mesh>
        </geometry>
      </visual>
    </link>
    <joint name='right_thigh_joint' type='revolute'>
      <child>right_thigh</child>
      <parent>base_link</parent>
      <axis>
        <xyz>0 1 0</xyz>
        <limit>
          <lower>-1</lower>
          <upper>1</upper>
          <effort>1000</effort>
          <velocity>0.5</velocity>
        </limit>
        <dynamics>
          <spring_reference>0</spring_reference>
          <spring_stiffness>0</spring_stiffness>
        </dynamics>
        <use_parent_model_frame>1</use_parent_model_frame>
      </axis>
    </joint>
    <link name='right_knee'>
      <pose frame=''>-0.0197 -8e-05 -0.027 0 -0 0</pose>
      <inertial>
        <pose frame=''>0 0 0 0 -0 0</pose>
        <mass>0.0005</mass>
        <inertia>
          <ixx>0.13</ixx>
          <ixy>0</ixy>
          <ixz>0</ixz>
          <iyy>0.21</iyy>
          <iyz>0</iyz>
          <izz>0.13</izz>
        </inertia>
      </inertial>
      <collision name='right_knee_collision'>
        <pose frame=''>0.012 -0.007 0.0067 3.14159 -0 3.14159</pose>
        <geometry>
          <mesh>
            <scale>0.01 0.01 0.01</scale>
            <uri>file:///home/jiovanni/catkin_ws/src/mob/urdf/RightKnee.dae</uri>
          </mesh>
        </geometry>
      </collision>
      <visual name='right_knee_visual'>
        <pose frame=''>0.012 -0.007 0.0067 3.14159 -0 3.14159</pose>
        <geometry>
          <mesh>
            <scale>0.01 0.01 0.01</scale>
            <uri>file:///home/jiovanni/catkin_ws/src/mob/urdf/RightKnee.dae</uri>
          </mesh>
        </geometry>
      </visual>
    </link>
    <joint name='right_knee_joint' type='revolute'>
      <child>right_knee</child>
      <parent>right_thigh</parent>
      <axis>
        <xyz>1 0 0</xyz>
        <limit>
          <lower>-1</lower>
          <upper>1</upper>
          <effort>1000</effort>
          <velocity>0.5</velocity>
        </limit>
        <dynamics>
          <spring_reference>0</spring_reference>
          <spring_stiffness>0</spring_stiffness>
        </dynamics>
        <use_parent_model_frame>1</use_parent_model_frame>
      </axis>
    </joint>
    <link name='right_shin'>
      <pose frame=''>-0.01996 -0.00016 -0.06 0 -0 0</pose>
      <inertial>
        <pose frame=''>0 0 0 0 -0 0</pose>
        <mass>0.0005</mass>
        <inertia>
          <ixx>0.13</ixx>
          <ixy>0</ixy>
          <ixz>0</ixz>
          <iyy>0.21</iyy>
          <iyz>0</iyz>
          <izz>0.13</izz>
        </inertia>
      </inertial>
      <collision name='right_shin_collision'>
        <pose frame=''>-0.0087 -0.0143 -0.0286 0 -0 0</pose>
        <geometry>
          <mesh>
            <scale>0.01 0.01 0.01</scale>
            <uri>file:///home/jiovanni/catkin_ws/src/mob/urdf/RightShin.dae</uri>
          </mesh>
        </geometry>
      </collision>
      <visual name='right_shin_visual'>
        <pose frame=''>-0.0087 -0.0143 -0.0286 0 -0 0</pose>
        <geometry>
          <mesh>
            <scale>0.01 0.01 0.01</scale>
            <uri>file:///home/jiovanni/catkin_ws/src/mob/urdf/RightShin.dae</uri>
          </mesh>
        </geometry>
      </visual>
    </link>
    <joint name='right_shin_joint' type='revolute'>
      <child>right_shin</child>
      <parent>right_knee</parent>
      <axis>
        <xyz>1 0 0</xyz>
        <limit>
          <lower>-1</lower>
          <upper>1</upper>
          <effort>1000</effort>
          <velocity>0.5</velocity>
        </limit>
        <dynamics>
          <spring_reference>0</spring_reference>
          <spring_stiffness>0</spring_stiffness>
        </dynamics>
        <use_parent_model_frame>1</use_parent_model_frame>
      </axis>
    </joint>
    <link name='right_ankle'>
      <pose frame=''>-0.02086 -0.00966 -0.084 0 -0 0</pose>
      <inertial>
        <pose frame=''>0 0 0 0 -0 0</pose>
        <mass>0.0005</mass>
        <inertia>
          <ixx>0.13</ixx>
          <ixy>0</ixy>
          <ixz>0</ixz>
          <iyy>0.21</iyy>
          <iyz>0</iyz>
          <izz>0.13</izz>
        </inertia>
      </inertial>
      <collision name='right_ankle_collision'>
        <pose frame=''>-0.0068 -0.0068 -0.0225 0 -0 0</pose>
        <geometry>
          <mesh>
            <scale>0.01 0.01 0.01</scale>
            <uri>file:///home/jiovanni/catkin_ws/src/mob/urdf/RightAnkle.dae</uri>
          </mesh>
        </geometry>
      </collision>
      <visual name='right_ankle_visual'>
        <pose frame=''>-0.0068 -0.0068 -0.0225 0 -0 0</pose>
        <geometry>
          <mesh>
            <scale>0.01 0.01 0.01</scale>
            <uri>file:///home/jiovanni/catkin_ws/src/mob/urdf/RightAnkle.dae</uri>
          </mesh>
        </geometry>
      </visual>
    </link>
    <joint name='right_ankle_joint' type='revolute'>
      <child>right_ankle</child>
      <parent>right_shin</parent>
      <axis>
        <xyz>1 0 0</xyz>
        <limit>
          <lower>-1</lower>
          <upper>1</upper>
          <effort>1000</effort>
          <velocity>0.5</velocity>
        </limit>
        <dynamics>
          <spring_reference>0</spring_reference>
          <spring_stiffness>0</spring_stiffness>
        </dynamics>
        <use_parent_model_frame>1</use_parent_model_frame>
      </axis>
    </joint>
    <link name='right_foot'>
      <pose frame=''>-0.01376 -0.01166 -0.102 0 -0 0</pose>
      <inertial>
        <pose frame=''>0 0 0 0 -0 0</pose>
        <mass>0.0005</mass>
        <inertia>
          <ixx>0.13</ixx>
          <ixy>0</ixy>
          <ixz>0</ixz>
          <iyy>0.21</iyy>
          <iyz>0</iyz>
          <izz>0.13</izz>
        </inertia>
      </inertial>
      <collision name='right_foot_collision'>
        <pose frame=''>-0.02 -0.026 -0.008 0 -0 0</pose>
        <geometry>
          <mesh>
            <scale>0.00046 0.00046 0.00046</scale>
            <uri>file:///home/jiovanni/catkin_ws/src/mob/urdf/RightFoot.dae</uri>
          </mesh>
        </geometry>
      </collision>
      <visual name='right_foot_visual'>
        <pose frame=''>-0.02 -0.026 -0.008 0 -0 0</pose>
        <geometry>
          <mesh>
            <scale>0.00046 0.00046 0.00046</scale>
            <uri>file:///home/jiovanni/catkin_ws/src/mob/urdf/RightFoot.dae</uri>
          </mesh>
        </geometry>
      </visual>
    </link>
    <joint name='right_foot_joint' type='revolute'>
      <child>right_foot</child>
      <parent>right_ankle</parent>
      <axis>
        <xyz>0 1 0</xyz>
        <limit>
          <lower>-1</lower>
          <upper>1</upper>
          <effort>1000</effort>
          <velocity>0.5</velocity>
        </limit>
        <dynamics>
          <spring_reference>0</spring_reference>
          <spring_stiffness>0</spring_stiffness>
        </dynamics>
        <use_parent_model_frame>1</use_parent_model_frame>
      </axis>
    </joint>
  </model>
</sdf>
