<?xml version='1.0'?>
<robot name="mob_robot">

  <!-- Base Link is waist bracket-->
  <link name="base_link">
    <visual>
      <origin xyz="0 0 0" rpy="0 4.71 0" />
      <geometry>
          <box size="0.02905 0.09013 0.04335"/>
      </geometry>
      <material name="darkgrey">
          <color rgba=".2 .2 .2 1" />
      </material>
    </visual>
    <!-- Collision on base_link-->
    <collision>
      <origin xyz="0 0 0" rpy="0 0 0" />
      <geometry>
          <box size="0.02905 0.09013 0.04335" />
      </geometry>
    </collision>
    <!--Mass in kilograms-->
    <inertial>
      <mass value="0.0005"/>
      <inertia ixx="0.13" ixy="0.0" ixz="0.0" iyy="0.21" iyz="0.0" izz="0.13" />
    </inertial>

    <!--chest bracket-->
    <visual>
      <origin xyz="0 0 0.027" rpy="0 0 0" />
      <geometry>
          <box size="0.0407 0.0197 0.0429"/>
      </geometry>
      <material name="darkgrey">
          <color rgba=".2 .2 .2 1" />
      </material>
    </visual>
    <collision>
      <origin xyz="0 0 0" rpy="0 0 0" />
      <geometry>
          <box size="0.407 0.197 0.429" />
      </geometry>
    </collision>
    <inertial>
      <mass value="0.055"/>
      <inertia ixx="0.13" ixy="0.0" ixz="0.0" iyy="0.21" iyz="0.0" izz="0.13" />
    </inertial>

    <!--right shoulder motor-->
    <visual>
      <origin xyz="0 0.03 0.027" rpy="0 0 0" />
      <geometry>
          <box size="0.0407 0.0197 0.0429"/>
      </geometry>
      <material name="darkgrey">
          <color rgba=".2 .2 .2 1" />
      </material>
    </visual>
    <collision>
      <origin xyz="0 0 0" rpy="0 0 0" />
      <geometry>
          <box size="0.407 0.197 0.429" />
      </geometry>
    </collision>
    <inertial>
      <mass value="0.055"/>
      <inertia ixx="0.13" ixy="0.0" ixz="0.0" iyy="0.21" iyz="0.0" izz="0.13" />
    </inertial>

    <!--left shoulder motor-->
    <visual>
      <origin xyz="0 -0.03 0.027" rpy="0 0 0" />
      <geometry>
          <box size="0.0407 0.0197 0.0429"/>
      </geometry>
      <material name="darkgrey">
          <color rgba=".2 .2 .2 1" />
      </material>
    </visual>
    <collision>
      <origin xyz="0 0 0" rpy="0 0 0" />
      <geometry>
          <box size="0.407 0.197 0.429" />
      </geometry>
    </collision>
    <inertial>
      <mass value="0.055"/>
      <inertia ixx="0.13" ixy="0.0" ixz="0.0" iyy="0.21" iyz="0.0" izz="0.13" />
    </inertial>
  </link>

    <!--head motor-->
  <link name="head_motor">
    <visual>
      <origin xyz="0 0 0" rpy="0 0 0" />
      <geometry>
          <box size="0.0407 0.0197 0.0429"/>
      </geometry>
      <material name="darkgrey">
          <color rgba=".2 .2 .2 1" />
      </material>
    </visual>
    <collision>
      <origin xyz="0 0 0" rpy="0 0 0" />
      <geometry>
          <box size="0.407 0.197 0.429" />
      </geometry>
    </collision>
    <inertial>
      <mass value="0.055"/>
      <inertia ixx="0.13" ixy="0.0" ixz="0.0" iyy="0.21" iyz="0.0" izz="0.13" />
    </inertial>
  </link>

  <!--This is the head/chest joint -->
  <joint name="head_joint" type="revolute">
    <limit effort="1000.0" lower="-1.0" upper="1.0" velocity="0.5"/>
    <parent link="base_link"/>
    <child link="head_motor"/>
    <origin xyz="0 0 0.07" rpy="0 0 0" />
    <axis xyz="0 0 1" />
  </joint>
</robot>
